Workbook

Sheet merchants
A1: merchant_id | B1: merchant_name | C1: category | D1: region
A2: 1 | B2: Merchant_001 | C2: ecommerce | D2: South
A3: 2 | B3: Merchant_002 | C3: grocery | D3: West
A4: 3 | B4: Merchant_003 | C4: grocery | D4: East
A5: 4 | B5: Merchant_004 | C5: ecommerce | D5: East
A6: 5 | B6: Merchant_005 | C6: recharge | D6: South
A7: 6 | B7: Merchant_006 | C7: food_delivery | D7: South
A8: 7 | B8: Merchant_007 | C8: food_delivery | D8: East
A9: 8 | B9: Merchant_008 | C9: food_delivery | D9: North
A10: 9 | B10: Merchant_009 | C10: ecommerce | D10: North
A11: 10 | B11: Merchant_010 | C11: grocery | D11: West
A12: 11 | B12: Merchant_011 | C12: ecommerce | D12: North
A13: 12 | B13: Merchant_012 | C13: ecommerce | D13: East
... A41: 40 | B41: Merchant_040 | C41: entertainment | D41: South

Sheet ledger
A1: transaction_id | B1: user_id | C1: merchant_id | D1: transaction_time | E1: amount_inr | F1: payment_method | G1: status | H1: risk_score
A2: TXN100000 | B2: 350 | C2: 16 | D2: 46051.467 | E2: 2999 | F2: Wallet | G2: captured | H2: 85
A3: TXN100001 | B3: 287 | C3: 27 | D3: 46026.492 | E3: 49 | F3: UPI | G3: captured | H3: 79
A4: TXN100002 | B4: 122 | C4: 11 | D4: 46046.208 | E4: 1499 | F4: Wallet | G4: captured | H4: 22
A5: TXN100003 | B5: 92 | C5: 22 | D5: 46051.542 | E5: 49 | F5: Netbanking | G5: captured | H5: 100
A6: TXN100004 | B6: 343 | C6: 16 | D6: 46052.577 | E6: 99 | F6: UPI | G6: captured | H6: 34
A7: TXN100005 | B7: 196 | C7: 3 | D7: 46028.921 | E7: 99 | F7: UPI | G7: captured | H7: 60
A8: TXN100006 | B8: 236 | C8: 23 | D8: 46030.286 | E8: 99 | F8: Wallet | G8: captured | H8: 39
A9: TXN100007 | B9: 13 | C9: 13 | D9: 46049.301 | E9: 99 | F9: UPI | G9: captured | H9: 51
A10: TXN100008 | B10: 36 | C10: 18 | D10: 46033.372 | E10: 799 | F10: UPI | G10: captured | H10: 44
A11: TXN100009 | B11: 348 | C11: 35 | D11: 46043.684 | E11: 299 | F11: UPI | G11: captured | H11: 42
A12: TXN100010 | B12: 134 | C12: 12 | D12: 46023.164 | E12: 49 | F12: UPI | G12: captured | H12: 74
A13: TXN100011 | B13: 306 | C13: 28 | D13: 46031.046 | E13: 2999 | F13: Card | G13: failed | H13: 44
... A548: TXN300031 | B548: 345 | C548: 12 | D548: 46045.377 | E548: 399 | F548: Card | G548: captured | H548: 69

Sheet merchant_workbook
A1: transaction_id | B1: user_id | C1: merchant_id | D1: transaction_time | E1: transaction_date | F1: amount_inr | G1: payment_method | H1: status | I1: risk_score | J1: merchant_name | K1: category | L1: region | M1: MDR_fee | N1: merchant_day_classification | P1: payment_method | Q1: Wallet | R1: UPI | S1: Netbanking | T1: Card
A2: TXN100000 | B2: 350 | C2: 16 | D2: 2026-01-29 11:13:00 | E2: =LEFT(D2,10) -> 2026-01-29 | F2: 2999 | G2: Wallet | H2: captured | I2: 85 | J2: =_xlfn.IFNA(VLOOKUP(C2,merchants!$A$1:$D$41,2,0),"Merchant not found") -> Merchant_016 | K2: =_xlfn.IFNA(VLOOKUP(C2,merchants!$A$1:$D$41,3,0),"Merchant not found") -> bill_payment | L2: =_xlfn.IFNA(VLOOKUP(C2,merchants!$A$1:$D$41,4,0),"Merchant not found") -> West | M2: =F2*(HLOOKUP(G2,$Q$1:$T$2,2,0)) -> 44.985 | N2: =IF(AND(L2<>"East",SUMIFS(merchant_workbook_pivot_table!$D$2:$D$444,merchant_workbook_pivot_table!$C$2:$C$444,E2,merchant_workbook_pivot_table!$B$2:$B$444,J2)>5000),"High-Value Merchant Day",IF(AND(L2<>"East",SUMIFS(merchant_workbook_pivot_table!$D$2:$D$444,merchant_workbook_pivot_table!$C$2:$C$444,E2,merchant_workbook_pivot_table!$B$2:$B$444,J2)>1000),"Mid-Value Merchant Day","")) -> Mid-Value Merchant Day | P2: MDR_fee_percentage | Q2: 0.015 | R2: 0 | S2: 0.01 | T2: 0.02
A3: TXN100001 | B3: 287 | C3: 27 | D3: 2026-01-04 11:49:00 | E3: =LEFT(D3,10) -> 2026-01-04 | F3: 49 | G3: UPI | H3: captured | I3: 79 | J3: =_xlfn.IFNA(VLOOKUP(C3,merchants!$A$1:$D$41,2,0),"Merchant not found") -> Merchant_027 | K3: =_xlfn.IFNA(VLOOKUP(C3,merchants!$A$1:$D$41,3,0),"Merchant not found") -> ecommerce | L3: =_xlfn.IFNA(VLOOKUP(C3,merchants!$A$1:$D$41,4,0),"Merchant not found") -> North | M3: =F3*(HLOOKUP(G3,$Q$1:$T$2,2,0)) -> 0 | N3: =IF(AND(L3<>"East",SUMIFS(merchant_workbook_pivot_table!$D$2:$D$444,merchant_workbook_pivot_table!$C$2:$C$444,E3,merchant_workbook_pivot_table!$B$2:$B$444,J3)>5000),"High-Value Merchant Day",IF(AND(L3<>"East",SUMIFS(merchant_workbook_pivot_table!$D$2:$D$444,merchant_workbook_pivot_table!$C$2:$C$444,E3,merchant_workbook_pivot_table!$B$2:$B$444,J3)>1000),"Mid-Value Merchant Day",""))
A4: TXN100002 | B4: 122 | C4: 11 | D4: 2026-01-24 4:59:00 | E4: =LEFT(D4,10) -> 2026-01-24 | F4: 1499 | G4: Wallet | H4: captured | I4: 22 | J4: =_xlfn.IFNA(VLOOKUP(C4,merchants!$A$1:$D$41,2,0),"Merchant not found") -> Merchant_011 | K4: =_xlfn.IFNA(VLOOKUP(C4,merchants!$A$1:$D$41,3,0),"Merchant not found") -> ecommerce | L4: =_xlfn.IFNA(VLOOKUP(C4,merchants!$A$1:$D$41,4,0),"Merchant not found") -> North | M4: =F4*(HLOOKUP(G4,$Q$1:$T$2,2,0)) -> 22.485 | N4: =IF(AND(L4<>"East",SUMIFS(merchant_workbook_pivot_table!$D$2:$D$444,merchant_workbook_pivot_table!$C$2:$C$444,E4,merchant_workbook_pivot_table!$B$2:$B$444,J4)>5000),"High-Value Merchant Day",IF(AND(L4<>"East",SUMIFS(merchant_workbook_pivot_table!$D$2:$D$444,merchant_workbook_pivot_table!$C$2:$C$444,E4,merchant_workbook_pivot_table!$B$2:$B$444,J4)>1000),"Mid-Value Merchant Day","")) -> Mid-Value Merchant Day | Q4: status | X4: merchant_name | Y4: transaction_days | Z4: transaction_count
A5: TXN100003 | B5: 92 | C5: 22 | D5: 2026-01-29 13:01:00 | E5: =LEFT(D5,10) -> 2026-01-29 | F5: 49 | G5: Netbanking | H5: captured | I5: 100 | J5: =_xlfn.IFNA(VLOOKUP(C5,merchants!$A$1:$D$41,2,0),"Merchant not found") -> Merchant_022 | K5: =_xlfn.IFNA(VLOOKUP(C5,merchants!$A$1:$D$41,3,0),"Merchant not found") -> travel | L5: =_xlfn.IFNA(VLOOKUP(C5,merchants!$A$1:$D$41,4,0),"Merchant not found") -> South | M5: =F5*(HLOOKUP(G5,$Q$1:$T$2,2,0)) -> 0.49 | N5: =IF(AND(L5<>"East",SUMIFS(merchant_workbook_pivot_table!$D$2:$D$444,merchant_workbook_pivot_table!$C$2:$C$444,E5,merchant_workbook_pivot_table!$B$2:$B$444,J5)>5000),"High-Value Merchant Day",IF(AND(L5<>"East",SUMIFS(merchant_workbook_pivot_table!$D$2:$D$444,merchant_workbook_pivot_table!$C$2:$C$444,E5,merchant_workbook_pivot_table!$B$2:$B$444,J5)>1000),"Mid-Value Merchant Day","")) | Q5: captured | S5: chargeback | U5: failed | X5: Merchant_001 | Y5: 7 | Z5: 9
A6: TXN100004 | B6: 343 | C6: 16 | D6: 2026-01-30 13:51:00 | E6: =LEFT(D6,10) -> 2026-01-30 | F6: 99 | G6: UPI | H6: captured | I6: 34 | J6: =_xlfn.IFNA(VLOOKUP(C6,merchants!$A$1:$D$41,2,0),"Merchant not found") -> Merchant_016 | K6: =_xlfn.IFNA(VLOOKUP(C6,merchants!$A$1:$D$41,3,0),"Merchant not found") -> bill_payment | L6: =_xlfn.IFNA(VLOOKUP(C6,merchants!$A$1:$D$41,4,0),"Merchant not found") -> West | M6: =F6*(HLOOKUP(G6,$Q$1:$T$2,2,0)) -> 0 | N6: =IF(AND(L6<>"East",SUMIFS(merchant_workbook_pivot_table!$D$2:$D$444,merchant_workbook_pivot_table!$C$2:$C$444,E6,merchant_workbook_pivot_table!$B$2:$B$444,J6)>5000),"High-Value Merchant Day",IF(AND(L6<>"East",SUMIFS(merchant_workbook_pivot_table!$D$2:$D$444,merchant_workbook_pivot_table!$C$2:$C$444,E6,merchant_workbook_pivot_table!$B$2:$B$444,J6)>1000),"Mid-Value Merchant Day","")) | P6: merchant_id | Q6: amount_inr | R6: transaction_count | S6: amount_inr | T6: transaction_count | U6: amount_inr | V6: transaction_count | X6: Merchant_002 | Y6: 9 | Z6: 10
A7: TXN100005 | B7: 196 | C7: 3 | D7: 2026-01-06 22:06:00 | E7: =LEFT(D7,10) -> 2026-01-06 | F7: 99 | G7: UPI | H7: captured | I7: 60 | J7: =_xlfn.IFNA(VLOOKUP(C7,merchants!$A$1:$D$41,2,0),"Merchant not found") -> Merchant_003 | K7: =_xlfn.IFNA(VLOOKUP(C7,merchants!$A$1:$D$41,3,0),"Merchant not found") -> grocery | L7: =_xlfn.IFNA(VLOOKUP(C7,merchants!$A$1:$D$41,4,0),"Merchant not found") -> East | M7: =F7*(HLOOKUP(G7,$Q$1:$T$2,2,0)) -> 0 | N7: =IF(AND(L7<>"East",SUMIFS(merchant_workbook_pivot_table!$D$2:$D$444,merchant_workbook_pivot_table!$C$2:$C$444,E7,merchant_workbook_pivot_table!$B$2:$B$444,J7)>5000),"High-Value Merchant Day",IF(AND(L7<>"East",SUMIFS(merchant_workbook_pivot_table!$D$2:$D$444,merchant_workbook_pivot_table!$C$2:$C$444,E7,merchant_workbook_pivot_table!$B$2:$B$444,J7)>1000),"Mid-Value Merchant Day","")) | P7: 1 | Q7: 10142 | R7: 8 | U7: 299 | V7: 1 | X7: Merchant_003 | Y7: 13 | Z7: 17
A8: TXN100006 | B8: 236 | C8: 23 | D8: 2026-01-08 6:52:00 | E8: =LEFT(D8,10) -> 2026-01-08 | F8: 99 | G8: Wallet | H8: captured | I8: 39 | J8: =_xlfn.IFNA(VLOOKUP(C8,merchants!$A$1:$D$41,2,0),"Merchant not found") -> Merchant_023 | K8: =_xlfn.IFNA(VLOOKUP(C8,merchants!$A$1:$D$41,3,0),"Merchant not found") -> travel | L8: =_xlfn.IFNA(VLOOKUP(C8,merchants!$A$1:$D$41,4,0),"Merchant not found") -> North | M8: =F8*(HLOOKUP(G8,$Q$1:$T$2,2,0)) -> 1.485 | N8: =IF(AND(L8<>"East",SUMIFS(merchant_workbook_pivot_table!$D$2:$D$444,merchant_workbook_pivot_table!$C$2:$C$444,E8,merchant_workbook_pivot_table!$B$2:$B$444,J8)>5000),"High-Value Merchant Day",IF(AND(L8<>"East",SUMIFS(merchant_workbook_pivot_table!$D$2:$D$444,merchant_workbook_pivot_table!$C$2:$C$444,E8,merchant_workbook_pivot_table!$B$2:$B$444,J8)>1000),"Mid-Value Merchant Day","")) | P8: 2 | Q8: 3640 | R8: 10 | X8: Merchant_004 | Y8: 7 | Z8: 9
A9: TXN100007 | B9: 13 | C9: 13 | D9: 2026-01-27 7:14:00 | E9: =LEFT(D9,10) -> 2026-01-27 | F9: 99 | G9: UPI | H9: captured | I9: 51 | J9: =_xlfn.IFNA(VLOOKUP(C9,merchants!$A$1:$D$41,2,0),"Merchant not found") -> Merchant_013 | K9: =_xlfn.IFNA(VLOOKUP(C9,merchants!$A$1:$D$41,3,0),"Merchant not found") -> travel | L9: =_xlfn.IFNA(VLOOKUP(C9,merchants!$A$1:$D$41,4,0),"Merchant not found") -> East | M9: =F9*(HLOOKUP(G9,$Q$1:$T$2,2,0)) -> 0 | N9: =IF(AND(L9<>"East",SUMIFS(merchant_workbook_pivot_table!$D$2:$D$444,merchant_workbook_pivot_table!$C$2:$C$444,E9,merchant_workbook_pivot_table!$B$2:$B$444,J9)>5000),"High-Value Merchant Day",IF(AND(L9<>"East",SUMIFS(merchant_workbook_pivot_table!$D$2:$D$444,merchant_workbook_pivot_table!$C$2:$C$444,E9,merchant_workbook_pivot_table!$B$2:$B$444,J9)>1000),"Mid-Value Merchant Day","")) | P9: 3 | Q9: 8084 | R9: 16 | S9: 149 | T9: 1 | X9: Merchant_005 | Y9: 9 | Z9: 11
A10: TXN100008 | B10: 36 | C10: 18 | D10: 2026-01-11 8:55:00 | E10: =LEFT(D10,10) -> 2026-01-11 | F10: 799 | G10: UPI | H10: captured | I10: 44 | J10: =_xlfn.IFNA(VLOOKUP(C10,merchants!$A$1:$D$41,2,0),"Merchant not found") -> Merchant_018 | K10: =_xlfn.IFNA(VLOOKUP(C10,merchants!$A$1:$D$41,3,0),"Merchant not found") -> grocery | L10: =_xlfn.IFNA(VLOOKUP(C10,merchants!$A$1:$D$41,4,0),"Merchant not found") -> West | M10: =F10*(HLOOKUP(G10,$Q$1:$T$2,2,0)) -> 0 | N10: =IF(AND(L10<>"East",SUMIFS(merchant_workbook_pivot_table!$D$2:$D$444,merchant_workbook_pivot_table!$C$2:$C$444,E10,merchant_workbook_pivot_table!$B$2:$B$444,J10)>5000),"High-Value Merchant Day",IF(AND(L10<>"East",SUMIFS(merchant_workbook_pivot_table!$D$2:$D$444,merchant_workbook_pivot_table!$C$2:$C$444,E10,merchant_workbook_pivot_table!$B$2:$B$444,J10)>1000),"Mid-Value Merchant Day","")) | P10: 4 | Q10: 6941 | R10: 9 | X10: Merchant_006 | Y10: 12 | Z10: 14
A11: TXN100009 | B11: 348 | C11: 35 | D11: 2026-01-21 16:25:00 | E11: =LEFT(D11,10) -> 2026-01-21 | F11: 299 | G11: UPI | H11: captured | I11: 42 | J11: =_xlfn.IFNA(VLOOKUP(C11,merchants!$A$1:$D$41,2,0),"Merchant not found") -> Merchant_035 | K11: =_xlfn.IFNA(VLOOKUP(C11,merchants!$A$1:$D$41,3,0),"Merchant not found") -> recharge | L11: =_xlfn.IFNA(VLOOKUP(C11,merchants!$A$1:$D$41,4,0),"Merchant not found") -> East | M11: =F11*(HLOOKUP(G11,$Q$1:$T$2,2,0)) -> 0 | N11: =IF(AND(L11<>"East",SUMIFS(merchant_workbook_pivot_table!$D$2:$D$444,merchant_workbook_pivot_table!$C$2:$C$444,E11,merchant_workbook_pivot_table!$B$2:$B$444,J11)>5000),"High-Value Merchant Day",IF(AND(L11<>"East",SUMIFS(merchant_workbook_pivot_table!$D$2:$D$444,merchant_workbook_pivot_table!$C$2:$C$444,E11,merchant_workbook_pivot_table!$B$2:$B$444,J11)>1000),"Mid-Value Merchant Day","")) | P11: 5 | Q11: 5340 | R11: 10 | U11: 499 | V11: 1 | X11: Merchant_007 | Y11: 11 | Z11: 16
A12: TXN100010 | B12: 134 | C12: 12 | D12: 2026-01-01 3:56:00 | E12: =LEFT(D12,10) -> 2026-01-01 | F12: 49 | G12: UPI | H12: captured | I12: 74 | J12: =_xlfn.IFNA(VLOOKUP(C12,merchants!$A$1:$D$41,2,0),"Merchant not found") -> Merchant_012 | K12: =_xlfn.IFNA(VLOOKUP(C12,merchants!$A$1:$D$41,3,0),"Merchant not found") -> ecommerce | L12: =_xlfn.IFNA(VLOOKUP(C12,merchants!$A$1:$D$41,4,0),"Merchant not found") -> East | M12: =F12*(HLOOKUP(G12,$Q$1:$T$2,2,0)) -> 0 | N12: =IF(AND(L12<>"East",SUMIFS(merchant_workbook_pivot_table!$D$2:$D$444,merchant_workbook_pivot_table!$C$2:$C$444,E12,merchant_workbook_pivot_table!$B$2:$B$444,J12)>5000),"High-Value Merchant Day",IF(AND(L12<>"East",SUMIFS(merchant_workbook_pivot_table!$D$2:$D$444,merchant_workbook_pivot_table!$C$2:$C$444,E12,merchant_workbook_pivot_table!$B$2:$B$444,J12)>1000),"Mid-Value Merchant Day","")) | P12: 6 | Q12: 6637 | R12: 13 | S12: 799 | T12: 1 | X12: Merchant_008 | Y12: 13 | Z12: 16
A13: TXN100011 | B13: 306 | C13: 28 | D13: 2026-01-09 1:06:00 | E13: =LEFT(D13,10) -> 2026-01-09 | F13: 2999 | G13: Card | H13: failed | I13: 44 | J13: =_xlfn.IFNA(VLOOKUP(C13,merchants!$A$1:$D$41,2,0),"Merchant not found") -> Merchant_028 | K13: =_xlfn.IFNA(VLOOKUP(C13,merchants!$A$1:$D$41,3,0),"Merchant not found") -> ecommerce | L13: =_xlfn.IFNA(VLOOKUP(C13,merchants!$A$1:$D$41,4,0),"Merchant not found") -> South | M13: =F13*(HLOOKUP(G13,$Q$1:$T$2,2,0)) -> 59.98 | N13: =IF(AND(L13<>"East",SUMIFS(merchant_workbook_pivot_table!$D$2:$D$444,merchant_workbook_pivot_table!$C$2:$C$444,E13,merchant_workbook_pivot_table!$B$2:$B$444,J13)>5000),"High-Value Merchant Day",IF(AND(L13<>"East",SUMIFS(merchant_workbook_pivot_table!$D$2:$D$444,merchant_workbook_pivot_table!$C$2:$C$444,E13,merchant_workbook_pivot_table!$B$2:$B$444,J13)>1000),"Mid-Value Merchant Day","")) -> Mid-Value Merchant Day | P13: 7 | Q13: 11638 | R13: 12 | S13: 1999 | T13: 1 | U13: 2297 | V13: 3 | X13: Merchant_009 | Y13: 14 | Z13: 18
A14: TXN100012 | B14: 311 | C14: 33 | D14: 2026-01-24 10:27:00 | E14: =LEFT(D14,10) -> 2026-01-24 | F14: 49 | G14: Wallet | H14: captured | I14: 14 | J14: =_xlfn.IFNA(VLOOKUP(C14,merchants!$A$1:$D$41,2,0),"Merchant not found") -> Merchant_033 | K14: =_xlfn.IFNA(VLOOKUP(C14,merchants!$A$1:$D$41,3,0),"Merchant not found") -> bill_payment | L14: =_xlfn.IFNA(VLOOKUP(C14,merchants!$A$1:$D$41,4,0),"Merchant not found") -> East | M14: =F14*(HLOOKUP(G14,$Q$1:$T$2,2,0)) -> 0.735 | N14: =IF(AND(L14<>"East",SUMIFS(merchant_workbook_pivot_table!$D$2:$D$444,merchant_workbook_pivot_table!$C$2:$C$444,E14,merchant_workbook_pivot_table!$B$2:$B$444,J14)>5000),"High-Value Merchant Day",IF(AND(L14<>"East",SUMIFS(merchant_workbook_pivot_table!$D$2:$D$444,merchant_workbook_pivot_table!$C$2:$C$444,E14,merchant_workbook_pivot_table!$B$2:$B$444,J14)>1000),"Mid-Value Merchant Day","")) | P14: 8 | Q14: 7086 | R14: 14 | S14: 49 | T14: 1 | U14: 299 | V14: 1 | X14: Merchant_010 | Y14: 12 | Z14: 14
A15: TXN100013 | B15: 131 | C15: 3 | D15: 2026-01-13 18:12:00 | E15: =LEFT(D15,10) -> 2026-01-13 | F15: 49 | G15: UPI | H15: captured | I15: 90 | J15: =_xlfn.IFNA(VLOOKUP(C15,merchants!$A$1:$D$41,2,0),"Merchant not found") -> Merchant_003 | K15: =_xlfn.IFNA(VLOOKUP(C15,merchants!$A$1:$D$41,3,0),"Merchant not found") -> grocery | L15: =_xlfn.IFNA(VLOOKUP(C15,merchants!$A$1:$D$41,4,0),"Merchant not found") -> East | M15: =F15*(HLOOKUP(G15,$Q$1:$T$2,2,0)) -> 0 | N15: =IF(AND(L15<>"East",SUMIFS(merchant_workbook_pivot_table!$D$2:$D$444,merchant_workbook_pivot_table!$C$2:$C$444,E15,merchant_workbook_pivot_table!$B$2:$B$444,J15)>5000),"High-Value Merchant Day",IF(AND(L15<>"East",SUMIFS(merchant_workbook_pivot_table!$D$2:$D$444,merchant_workbook_pivot_table!$C$2:$C$444,E15,merchant_workbook_pivot_table!$B$2:$B$444,J15)>1000),"Mid-Value Merchant Day","")) | P15: 9 | Q15: 4485 | R15: 15 | U15: 497 | V15: 3 | X15: Merchant_011 | Y15: 9 | Z15: 10
A16: TXN100014 | B16: 276 | C16: 13 | D16: 2026-01-14 0:33:00 | E16: =LEFT(D16,10) -> 2026-01-14 | F16: 1499 | G16: UPI | H16: captured | I16: 46 | J16: =_xlfn.IFNA(VLOOKUP(C16,merchants!$A$1:$D$41,2,0),"Merchant not found") -> Merchant_013 | K16: =_xlfn.IFNA(VLOOKUP(C16,merchants!$A$1:$D$41,3,0),"Merchant not found") -> travel | L16: =_xlfn.IFNA(VLOOKUP(C16,merchants!$A$1:$D$41,4,0),"Merchant not found") -> East | M16: =F16*(HLOOKUP(G16,$Q$1:$T$2,2,0)) -> 0 | N16: =IF(AND(L16<>"East",SUMIFS(merchant_workbook_pivot_table!$D$2:$D$444,merchant_workbook_pivot_table!$C$2:$C$444,E16,merchant_workbook_pivot_table!$B$2:$B$444,J16)>5000),"High-Value Merchant Day",IF(AND(L16<>"East",SUMIFS(merchant_workbook_pivot_table!$D$2:$D$444,merchant_workbook_pivot_table!$C$2:$C$444,E16,merchant_workbook_pivot_table!$B$2:$B$444,J16)>1000),"Mid-Value Merchant Day","")) | P16: 10 | Q16: 7639 | R16: 11 | S16: 5048 | T16: 2 | U16: 399 | V16: 1 | X16: Merchant_012 | Y16: 9 | Z16: 13
A17: TXN100015 | B17: 170 | C17: 40 | D17: 2026-01-14 2:42:00 | E17: =LEFT(D17,10) -> 2026-01-14 | F17: 99 | G17: UPI | H17: captured | I17: 40 | J17: =_xlfn.IFNA(VLOOKUP(C17,merchants!$A$1:$D$41,2,0),"Merchant not found") -> Merchant_040 | K17: =_xlfn.IFNA(VLOOKUP(C17,merchants!$A$1:$D$41,3,0),"Merchant not found") -> entertainment | L17: =_xlfn.IFNA(VLOOKUP(C17,merchants!$A$1:$D$41,4,0),"Merchant not found") -> South | M17: =F17*(HLOOKUP(G17,$Q$1:$T$2,2,0)) -> 0 | N17: =IF(AND(L17<>"East",SUMIFS(merchant_workbook_pivot_table!$D$2:$D$444,merchant_workbook_pivot_table!$C$2:$C$444,E17,merchant_workbook_pivot_table!$B$2:$B$444,J17)>5000),"High-Value Merchant Day",IF(AND(L17<>"East",SUMIFS(merchant_workbook_pivot_table!$D$2:$D$444,merchant_workbook_pivot_table!$C$2:$C$444,E17,merchant_workbook_pivot_table!$B$2:$B$444,J17)>1000),"Mid-Value Merchant Day","")) | P17: 11 | Q17: 9292 | R17: 8 | S17: 149 | T17: 1 | U17: 1499 | V17: 1 | X17: Merchant_013 | Y17: 11 | Z17: 12
A18: TXN100016 | B18: 154 | C18: 33 | D18: 2026-01-22 3:46:00 | E18: =LEFT(D18,10) -> 2026-01-22 | F18: 99 | G18: Netbanking | H18: captured | I18: 39 | J18: =_xlfn.IFNA(VLOOKUP(C18,merchants!$A$1:$D$41,2,0),"Merchant not found") -> Merchant_033 | K18: =_xlfn.IFNA(VLOOKUP(C18,merchants!$A$1:$D$41,3,0),"Merchant not found") -> bill_payment | L18: =_xlfn.IFNA(VLOOKUP(C18,merchants!$A$1:$D$41,4,0),"Merchant not found") -> East | M18: =F18*(HLOOKUP(G18,$Q$1:$T$2,2,0)) -> 0.99 | N18: =IF(AND(L18<>"East",SUMIFS(merchant_workbook_pivot_table!$D$2:$D$444,merchant_workbook_pivot_table!$C$2:$C$444,E18,merchant_workbook_pivot_table!$B$2:$B$444,J18)>5000),"High-Value Merchant Day",IF(AND(L18<>"East",SUMIFS(merchant_workbook_pivot_table!$D$2:$D$444,merchant_workbook_pivot_table!$C$2:$C$444,E18,merchant_workbook_pivot_table!$B$2:$B$444,J18)>1000),"Mid-Value Merchant Day","")) | P18: 12 | Q18: 9389 | R18: 11 | U18: 998 | V18: 2 | X18: Merchant_014 | Y18: 11 | Z18: 12
A19: TXN100017 | B19: 207 | C19: 19 | D19: 2026-01-22 13:20:00 | E19: =LEFT(D19,10) -> 2026-01-22 | F19: 2999 | G19: Card | H19: captured | I19: 70 | J19: =_xlfn.IFNA(VLOOKUP(C19,merchants!$A$1:$D$41,2,0),"Merchant not found") -> Merchant_019 | K19: =_xlfn.IFNA(VLOOKUP(C19,merchants!$A$1:$D$41,3,0),"Merchant not found") -> grocery | L19: =_xlfn.IFNA(VLOOKUP(C19,merchants!$A$1:$D$41,4,0),"Merchant not found") -> North | M19: =F19*(HLOOKUP(G19,$Q$1:$T$2,2,0)) -> 59.98 | N19: =IF(AND(L19<>"East",SUMIFS(merchant_workbook_pivot_table!$D$2:$D$444,merchant_workbook_pivot_table!$C$2:$C$444,E19,merchant_workbook_pivot_table!$B$2:$B$444,J19)>5000),"High-Value Merchant Day",IF(AND(L19<>"East",SUMIFS(merchant_workbook_pivot_table!$D$2:$D$444,merchant_workbook_pivot_table!$C$2:$C$444,E19,merchant_workbook_pivot_table!$B$2:$B$444,J19)>1000),"Mid-Value Merchant Day","")) -> Mid-Value Merchant Day | P19: 13 | Q19: 10390 | R19: 10 | S19: 4999 | T19: 1 | U19: 2999 | V19: 1 | X19: Merchant_015 | Y19: 10 | Z19: 12
A20: TXN100018 | B20: 341 | C20: 25 | D20: 2026-01-05 6:26:00 | E20: =LEFT(D20,10) -> 2026-01-05 | F20: 2999 | G20: UPI | H20: captured | I20: 86 | J20: =_xlfn.IFNA(VLOOKUP(C20,merchants!$A$1:$D$41,2,0),"Merchant not found") -> Merchant_025 | K20: =_xlfn.IFNA(VLOOKUP(C20,merchants!$A$1:$D$41,3,0),"Merchant not found") -> travel | L20: =_xlfn.IFNA(VLOOKUP(C20,merchants!$A$1:$D$41,4,0),"Merchant not found") -> South | M20: =F20*(HLOOKUP(G20,$Q$1:$T$2,2,0)) -> 0 | N20: =IF(AND(L20<>"East",SUMIFS(merchant_workbook_pivot_table!$D$2:$D$444,merchant_workbook_pivot_table!$C$2:$C$444,E20,merchant_workbook_pivot_table!$B$2:$B$444,J20)>5000),"High-Value Merchant Day",IF(AND(L20<>"East",SUMIFS(merchant_workbook_pivot_table!$D$2:$D$444,merchant_workbook_pivot_table!$C$2:$C$444,E20,merchant_workbook_pivot_table!$B$2:$B$444,J20)>1000),"Mid-Value Merchant Day","")) -> Mid-Value Merchant Day | P20: 14 | Q20: 6189 | R20: 11 | U20: 299 | V20: 1 | X20: Merchant_016 | Y20: 15 | Z20: 20
A21: TXN100019 | B21: 292 | C21: 20 | D21: 2026-01-24 5:39:00 | E21: =LEFT(D21,10) -> 2026-01-24 | F21: 49 | G21: UPI | H21: captured | I21: 51 | J21: =_xlfn.IFNA(VLOOKUP(C21,merchants!$A$1:$D$41,2,0),"Merchant not found") -> Merchant_020 | K21: =_xlfn.IFNA(VLOOKUP(C21,merchants!$A$1:$D$41,3,0),"Merchant not found") -> food_delivery | L21: =_xlfn.IFNA(VLOOKUP(C21,merchants!$A$1:$D$41,4,0),"Merchant not found") -> East | M21: =F21*(HLOOKUP(G21,$Q$1:$T$2,2,0)) -> 0 | N21: =IF(AND(L21<>"East",SUMIFS(merchant_workbook_pivot_table!$D$2:$D$444,merchant_workbook_pivot_table!$C$2:$C$444,E21,merchant_workbook_pivot_table!$B$2:$B$444,J21)>5000),"High-Value Merchant Day",IF(AND(L21<>"East",SUMIFS(merchant_workbook_pivot_table!$D$2:$D$444,merchant_workbook_pivot_table!$C$2:$C$444,E21,merchant_workbook_pivot_table!$B$2:$B$444,J21)>1000),"Mid-Value Merchant Day","")) | P21: 15 | Q21: 7439 | R21: 11 | U21: 399 | V21: 1 | X21: Merchant_017 | Y21: 10 | Z21: 13
A22: TXN100020 | B22: 147 | C22: 14 | D22: 2026-01-18 0:19:00 | E22: =LEFT(D22,10) -> 2026-01-18 | F22: 99 | G22: Card | H22: captured | I22: 55 | J22: =_xlfn.IFNA(VLOOKUP(C22,merchants!$A$1:$D$41,2,0),"Merchant not found") -> Merchant_014 | K22: =_xlfn.IFNA(VLOOKUP(C22,merchants!$A$1:$D$41,3,0),"Merchant not found") -> grocery | L22: =_xlfn.IFNA(VLOOKUP(C22,merchants!$A$1:$D$41,4,0),"Merchant not found") -> East | M22: =F22*(HLOOKUP(G22,$Q$1:$T$2,2,0)) -> 1.98 | N22: =IF(AND(L22<>"East",SUMIFS(merchant_workbook_pivot_table!$D$2:$D$444,merchant_workbook_pivot_table!$C$2:$C$444,E22,merchant_workbook_pivot_table!$B$2:$B$444,J22)>5000),"High-Value Merchant Day",IF(AND(L22<>"East",SUMIFS(merchant_workbook_pivot_table!$D$2:$D$444,merchant_workbook_pivot_table!$C$2:$C$444,E22,merchant_workbook_pivot_table!$B$2:$B$444,J22)>1000),"Mid-Value Merchant Day","")) | P22: 16 | Q22: 10183 | R22: 17 | U22: 947 | V22: 3 | X22: Merchant_018 | Y22: 9 | Z22: 11
A23: TXN100021 | B23: 336 | C23: 21 | D23: 2026-01-26 18:38:00 | E23: =LEFT(D23,10) -> 2026-01-26 | F23: 99 | G23: UPI | H23: captured | I23: 59 | J23: =_xlfn.IFNA(VLOOKUP(C23,merchants!$A$1:$D$41,2,0),"Merchant not found") -> Merchant_021 | K23: =_xlfn.IFNA(VLOOKUP(C23,merchants!$A$1:$D$41,3,0),"Merchant not found") -> food_delivery | L23: =_xlfn.IFNA(VLOOKUP(C23,merchants!$A$1:$D$41,4,0),"Merchant not found") -> East | M23: =F23*(HLOOKUP(G23,$Q$1:$T$2,2,0)) -> 0 | N23: =IF(AND(L23<>"East",SUMIFS(merchant_workbook_pivot_table!$D$2:$D$444,merchant_workbook_pivot_table!$C$2:$C$444,E23,merchant_workbook_pivot_table!$B$2:$B$444,J23)>5000),"High-Value Merchant Day",IF(AND(L23<>"East",SUMIFS(merchant_workbook_pivot_table!$D$2:$D$444,merchant_workbook_pivot_table!$C$2:$C$444,E23,merchant_workbook_pivot_table!$B$2:$B$444,J23)>1000),"Mid-Value Merchant Day","")) | P23: 17 | Q23: 12738 | R23: 12 | U23: 299 | V23: 1 | X23: Merchant_019 | Y23: 12 | Z23: 14
A24: TXN100022 | B24: 110 | C24: 33 | D24: 2026-01-15 14:43:00 | E24: =LEFT(D24,10) -> 2026-01-15 | F24: 799 | G24: UPI | H24: captured | I24: 60 | J24: =_xlfn.IFNA(VLOOKUP(C24,merchants!$A$1:$D$41,2,0),"Merchant not found") -> Merchant_033 | K24: =_xlfn.IFNA(VLOOKUP(C24,merchants!$A$1:$D$41,3,0),"Merchant not found") -> bill_payment | L24: =_xlfn.IFNA(VLOOKUP(C24,merchants!$A$1:$D$41,4,0),"Merchant not found") -> East | M24: =F24*(HLOOKUP(G24,$Q$1:$T$2,2,0)) -> 0 | N24: =IF(AND(L24<>"East",SUMIFS(merchant_workbook_pivot_table!$D$2:$D$444,merchant_workbook_pivot_table!$C$2:$C$444,E24,merchant_workbook_pivot_table!$B$2:$B$444,J24)>5000),"High-Value Merchant Day",IF(AND(L24<>"East",SUMIFS(merchant_workbook_pivot_table!$D$2:$D$444,merchant_workbook_pivot_table!$C$2:$C$444,E24,merchant_workbook_pivot_table!$B$2:$B$444,J24)>1000),"Mid-Value Merchant Day","")) | P24: 18 | Q24: 7089 | R24: 11 | X24: Merchant_020 | Y24: 8 | Z24: 9
A25: TXN100023 | B25: 338 | C25: 6 | D25: 2026-01-26 23:10:00 | E25: =LEFT(D25,10) -> 2026-01-26 | F25: 799 | G25: UPI | H25: chargeback | I25: 36 | J25: =_xlfn.IFNA(VLOOKUP(C25,merchants!$A$1:$D$41,2,0),"Merchant not found") -> Merchant_006 | K25: =_xlfn.IFNA(VLOOKUP(C25,merchants!$A$1:$D$41,3,0),"Merchant not found") -> food_delivery | L25: =_xlfn.IFNA(VLOOKUP(C25,merchants!$A$1:$D$41,4,0),"Merchant not found") -> South | M25: =F25*(HLOOKUP(G25,$Q$1:$T$2,2,0)) -> 0 | N25: =IF(AND(L25<>"East",SUMIFS(merchant_workbook_pivot_table!$D$2:$D$444,merchant_workbook_pivot_table!$C$2:$C$444,E25,merchant_workbook_pivot_table!$B$2:$B$444,J25)>5000),"High-Value Merchant Day",IF(AND(L25<>"East",SUMIFS(merchant_workbook_pivot_table!$D$2:$D$444,merchant_workbook_pivot_table!$C$2:$C$444,E25,merchant_workbook_pivot_table!$B$2:$B$444,J25)>1000),"Mid-Value Merchant Day","")) | P25: 19 | Q25: 7239 | R25: 11 | S25: 4999 | T25: 1 | U25: 598 | V25: 2 | X25: Merchant_021 | Y25: 13 | Z25: 14
A26: TXN100024 | B26: 318 | C26: 22 | D26: 2026-01-17 21:40:00 | E26: =LEFT(D26,10) -> 2026-01-17 | F26: 799 | G26: Wallet | H26: captured | I26: 11 | J26: =_xlfn.IFNA(VLOOKUP(C26,merchants!$A$1:$D$41,2,0),"Merchant not found") -> Merchant_022 | K26: =_xlfn.IFNA(VLOOKUP(C26,merchants!$A$1:$D$41,3,0),"Merchant not found") -> travel | L26: =_xlfn.IFNA(VLOOKUP(C26,merchants!$A$1:$D$41,4,0),"Merchant not found") -> South | M26: =F26*(HLOOKUP(G26,$Q$1:$T$2,2,0)) -> 11.985 | N26: =IF(AND(L26<>"East",SUMIFS(merchant_workbook_pivot_table!$D$2:$D$444,merchant_workbook_pivot_table!$C$2:$C$444,E26,merchant_workbook_pivot_table!$B$2:$B$444,J26)>5000),"High-Value Merchant Day",IF(AND(L26<>"East",SUMIFS(merchant_workbook_pivot_table!$D$2:$D$444,merchant_workbook_pivot_table!$C$2:$C$444,E26,merchant_workbook_pivot_table!$B$2:$B$444,J26)>1000),"Mid-Value Merchant Day","")) -> Mid-Value Merchant Day | P26: 20 | Q26: 4192 | R26: 8 | U26: 49 | V26: 1 | X26: Merchant_022 | Y26: 11 | Z26: 16
A27: TXN100025 | B27: 159 | C27: 15 | D27: 2026-01-27 7:43:00 | E27: =LEFT(D27,10) -> 2026-01-27 | F27: 799 | G27: UPI | H27: captured | I27: 25 | J27: =_xlfn.IFNA(VLOOKUP(C27,merchants!$A$1:$D$41,2,0),"Merchant not found") -> Merchant_015 | K27: =_xlfn.IFNA(VLOOKUP(C27,merchants!$A$1:$D$41,3,0),"Merchant not found") -> travel | L27: =_xlfn.IFNA(VLOOKUP(C27,merchants!$A$1:$D$41,4,0),"Merchant not found") -> North | M27: =F27*(HLOOKUP(G27,$Q$1:$T$2,2,0)) -> 0 | N27: =IF(AND(L27<>"East",SUMIFS(merchant_workbook_pivot_table!$D$2:$D$444,merchant_workbook_pivot_table!$C$2:$C$444,E27,merchant_workbook_pivot_table!$B$2:$B$444,J27)>5000),"High-Value Merchant Day",IF(AND(L27<>"East",SUMIFS(merchant_workbook_pivot_table!$D$2:$D$444,merchant_workbook_pivot_table!$C$2:$C$444,E27,merchant_workbook_pivot_table!$B$2:$B$444,J27)>1000),"Mid-Value Merchant Day","")) | P27: 21 | Q27: 3887 | R27: 13 | U27: 4999 | V27: 1 | X27: Merchant_023 | Y27: 8 | Z27: 10
A28: TXN100026 | B28: 126 | C28: 31 | D28: 2026-01-05 0:02:00 | E28: =LEFT(D28,10) -> 2026-01-05 | F28: 49 | G28: Card | H28: captured | I28: 78 | J28: =_xlfn.IFNA(VLOOKUP(C28,merchants!$A$1:$D$41,2,0),"Merchant not found") -> Merchant_031 | K28: =_xlfn.IFNA(VLOOKUP(C28,merchants!$A$1:$D$41,3,0),"Merchant not found") -> bill_payment | L28: =_xlfn.IFNA(VLOOKUP(C28,merchants!$A$1:$D$41,4,0),"Merchant not found") -> East | M28: =F28*(HLOOKUP(G28,$Q$1:$T$2,2,0)) -> 0.98 | N28: =IF(AND(L28<>"East",SUMIFS(merchant_workbook_pivot_table!$D$2:$D$444,merchant_workbook_pivot_table!$C$2:$C$444,E28,merchant_workbook_pivot_table!$B$2:$B$444,J28)>5000),"High-Value Merchant Day",IF(AND(L28<>"East",SUMIFS(merchant_workbook_pivot_table!$D$2:$D$444,merchant_workbook_pivot_table!$C$2:$C$444,E28,merchant_workbook_pivot_table!$B$2:$B$444,J28)>1000),"Mid-Value Merchant Day","")) | P28: 22 | Q28: 11336 | R28: 14 | U28: 1198 | V28: 2 | X28: Merchant_024 | Y28: 11 | Z28: 13
A29: TXN100027 | B29: 213 | C29: 37 | D29: 2026-01-28 2:29:00 | E29: =LEFT(D29,10) -> 2026-01-28 | F29: 99 | G29: UPI | H29: captured | I29: 24 | J29: =_xlfn.IFNA(VLOOKUP(C29,merchants!$A$1:$D$41,2,0),"Merchant not found") -> Merchant_037 | K29: =_xlfn.IFNA(VLOOKUP(C29,merchants!$A$1:$D$41,3,0),"Merchant not found") -> entertainment | L29: =_xlfn.IFNA(VLOOKUP(C29,merchants!$A$1:$D$41,4,0),"Merchant not found") -> South | M29: =F29*(HLOOKUP(G29,$Q$1:$T$2,2,0)) -> 0 | N29: =IF(AND(L29<>"East",SUMIFS(merchant_workbook_pivot_table!$D$2:$D$444,merchant_workbook_pivot_table!$C$2:$C$444,E29,merchant_workbook_pivot_table!$B$2:$B$444,J29)>5000),"High-Value Merchant Day",IF(AND(L29<>"East",SUMIFS(merchant_workbook_pivot_table!$D$2:$D$444,merchant_workbook_pivot_table!$C$2:$C$444,E29,merchant_workbook_pivot_table!$B$2:$B$444,J29)>1000),"Mid-Value Merchant Day","")) | P29: 23 | Q29: 1041 | R29: 9 | S29: 1999 | T29: 1 | X29: Merchant_025 | Y29: 11 | Z29: 17
A30: TXN100028 | B30: 254 | C30: 26 | D30: 2026-01-23 22:24:00 | E30: =LEFT(D30,10) -> 2026-01-23 | F30: 99 | G30: Wallet | H30: captured | I30: 31 | J30: =_xlfn.IFNA(VLOOKUP(C30,merchants!$A$1:$D$41,2,0),"Merchant not found") -> Merchant_026 | K30: =_xlfn.IFNA(VLOOKUP(C30,merchants!$A$1:$D$41,3,0),"Merchant not found") -> food_delivery | L30: =_xlfn.IFNA(VLOOKUP(C30,merchants!$A$1:$D$41,4,0),"Merchant not found") -> East | M30: =F30*(HLOOKUP(G30,$Q$1:$T$2,2,0)) -> 1.485 | N30: =IF(AND(L30<>"East",SUMIFS(merchant_workbook_pivot_table!$D$2:$D$444,merchant_workbook_pivot_table!$C$2:$C$444,E30,merchant_workbook_pivot_table!$B$2:$B$444,J30)>5000),"High-Value Merchant Day",IF(AND(L30<>"East",SUMIFS(merchant_workbook_pivot_table!$D$2:$D$444,merchant_workbook_pivot_table!$C$2:$C$444,E30,merchant_workbook_pivot_table!$B$2:$B$444,J30)>1000),"Mid-Value Merchant Day","")) | P30: 24 | Q30: 3438 | R30: 12 | S30: 149 | T30: 1 | X30: Merchant_026 | Y30: 11 | Z30: 12
A31: TXN100029 | B31: 3 | C31: 7 | D31: 2026-01-05 20:44:00 | E31: =LEFT(D31,10) -> 2026-01-05 | F31: 1499 | G31: UPI | H31: captured | I31: 99 | J31: =_xlfn.IFNA(VLOOKUP(C31,merchants!$A$1:$D$41,2,0),"Merchant not found") -> Merchant_007 | K31: =_xlfn.IFNA(VLOOKUP(C31,merchants!$A$1:$D$41,3,0),"Merchant not found") -> food_delivery | L31: =_xlfn.IFNA(VLOOKUP(C31,merchants!$A$1:$D$41,4,0),"Merchant not found") -> East | M31: =F31*(HLOOKUP(G31,$Q$1:$T$2,2,0)) -> 0 | N31: =IF(AND(L31<>"East",SUMIFS(merchant_workbook_pivot_table!$D$2:$D$444,merchant_workbook_pivot_table!$C$2:$C$444,E31,merchant_workbook_pivot_table!$B$2:$B$444,J31)>5000),"High-Value Merchant Day",IF(AND(L31<>"East",SUMIFS(merchant_workbook_pivot_table!$D$2:$D$444,merchant_workbook_pivot_table!$C$2:$C$444,E31,merchant_workbook_pivot_table!$B$2:$B$444,J31)>1000),"Mid-Value Merchant Day","")) | P31: 25 | Q31: 12534 | R31: 16 | S31: 2999 | T31: 1 | X31: Merchant_027 | Y31: 13 | Z31: 16
A32: TXN100030 | B32: 266 | C32: 30 | D32: 2026-01-14 7:11:00 | E32: =LEFT(D32,10) -> 2026-01-14 | F32: 499 | G32: Card | H32: captured | I32: 6 | J32: =_xlfn.IFNA(VLOOKUP(C32,merchants!$A$1:$D$41,2,0),"Merchant not found") -> Merchant_030 | K32: =_xlfn.IFNA(VLOOKUP(C32,merchants!$A$1:$D$41,3,0),"Merchant not found") -> travel | L32: =_xlfn.IFNA(VLOOKUP(C32,merchants!$A$1:$D$41,4,0),"Merchant not found") -> West | M32: =F32*(HLOOKUP(G32,$Q$1:$T$2,2,0)) -> 9.98 | N32: =IF(AND(L32<>"East",SUMIFS(merchant_workbook_pivot_table!$D$2:$D$444,merchant_workbook_pivot_table!$C$2:$C$444,E32,merchant_workbook_pivot_table!$B$2:$B$444,J32)>5000),"High-Value Merchant Day",IF(AND(L32<>"East",SUMIFS(merchant_workbook_pivot_table!$D$2:$D$444,merchant_workbook_pivot_table!$C$2:$C$444,E32,merchant_workbook_pivot_table!$B$2:$B$444,J32)>1000),"Mid-Value Merchant Day","")) -> Mid-Value Merchant Day | P32: 26 | Q32: 2991 | R32: 9 | U32: 2197 | V32: 3 | X32: Merchant_028 | Y32: 10 | Z32: 10
A33: TXN100031 | B33: 63 | C33: 30 | D33: 2026-01-18 7:58:00 | E33: =LEFT(D33,10) -> 2026-01-18 | F33: 799 | G33: UPI | H33: captured | I33: 17 | J33: =_xlfn.IFNA(VLOOKUP(C33,merchants!$A$1:$D$41,2,0),"Merchant not found") -> Merchant_030 | K33: =_xlfn.IFNA(VLOOKUP(C33,merchants!$A$1:$D$41,3,0),"Merchant not found") -> travel | L33: =_xlfn.IFNA(VLOOKUP(C33,merchants!$A$1:$D$41,4,0),"Merchant not found") -> West | M33: =F33*(HLOOKUP(G33,$Q$1:$T$2,2,0)) -> 0 | N33: =IF(AND(L33<>"East",SUMIFS(merchant_workbook_pivot_table!$D$2:$D$444,merchant_workbook_pivot_table!$C$2:$C$444,E33,merchant_workbook_pivot_table!$B$2:$B$444,J33)>5000),"High-Value Merchant Day",IF(AND(L33<>"East",SUMIFS(merchant_workbook_pivot_table!$D$2:$D$444,merchant_workbook_pivot_table!$C$2:$C$444,E33,merchant_workbook_pivot_table!$B$2:$B$444,J33)>1000),"Mid-Value Merchant Day","")) | P33: 27 | Q33: 8038 | R33: 12 | S33: 4047 | T33: 3 | U33: 1499 | V33: 1 | X33: Merchant_029 | Y33: 13 | Z33: 19
A34: TXN100032 | B34: 272 | C34: 36 | D34: 2026-01-26 14:42:00 | E34: =LEFT(D34,10) -> 2026-01-26 | F34: 149 | G34: UPI | H34: captured | I34: 76 | J34: =_xlfn.IFNA(VLOOKUP(C34,merchants!$A$1:$D$41,2,0),"Merchant not found") -> Merchant_036 | K34: =_xlfn.IFNA(VLOOKUP(C34,merchants!$A$1:$D$41,3,0),"Merchant not found") -> entertainment | L34: =_xlfn.IFNA(VLOOKUP(C34,merchants!$A$1:$D$41,4,0),"Merchant not found") -> East | M34: =F34*(HLOOKUP(G34,$Q$1:$T$2,2,0)) -> 0 | N34: =IF(AND(L34<>"East",SUMIFS(merchant_workbook_pivot_table!$D$2:$D$444,merchant_workbook_pivot_table!$C$2:$C$444,E34,merchant_workbook_pivot_table!$B$2:$B$444,J34)>5000),"High-Value Merchant Day",IF(AND(L34<>"East",SUMIFS(merchant_workbook_pivot_table!$D$2:$D$444,merchant_workbook_pivot_table!$C$2:$C$444,E34,merchant_workbook_pivot_table!$B$2:$B$444,J34)>1000),"Mid-Value Merchant Day","")) | P34: 28 | Q34: 4493 | R34: 7 | S34: 1999 | T34: 1 | U34: 3048 | V34: 2 | X34: Merchant_030 | Y34: 13 | Z34: 17
A35: TXN100033 | B35: 259 | C35: 28 | D35: 2026-01-11 14:39:00 | E35: =LEFT(D35,10) -> 2026-01-11 | F35: 49 | G35: Wallet | H35: captured | I35: 70 | J35: =_xlfn.IFNA(VLOOKUP(C35,merchants!$A$1:$D$41,2,0),"Merchant not found") -> Merchant_028 | K35: =_xlfn.IFNA(VLOOKUP(C35,merchants!$A$1:$D$41,3,0),"Merchant not found") -> ecommerce | L35: =_xlfn.IFNA(VLOOKUP(C35,merchants!$A$1:$D$41,4,0),"Merchant not found") -> South | M35: =F35*(HLOOKUP(G35,$Q$1:$T$2,2,0)) -> 0.735 | N35: =IF(AND(L35<>"East",SUMIFS(merchant_workbook_pivot_table!$D$2:$D$444,merchant_workbook_pivot_table!$C$2:$C$444,E35,merchant_workbook_pivot_table!$B$2:$B$444,J35)>5000),"High-Value Merchant Day",IF(AND(L35<>"East",SUMIFS(merchant_workbook_pivot_table!$D$2:$D$444,merchant_workbook_pivot_table!$C$2:$C$444,E35,merchant_workbook_pivot_table!$B$2:$B$444,J35)>1000),"Mid-Value Merchant Day","")) | P35: 29 | Q35: 5686 | R35: 14 | S35: 3897 | T35: 3 | U35: 3498 | V35: 2 | X35: Merchant_031 | Y35: 14 | Z35: 15
A36: TXN100034 | B36: 244 | C36: 29 | D36: 2026-01-15 5:47:00 | E36: =LEFT(D36,10) -> 2026-01-15 | F36: 299 | G36: Netbanking | H36: captured | I36: 33 | J36: =_xlfn.IFNA(VLOOKUP(C36,merchants!$A$1:$D$41,2,0),"Merchant not found") -> Merchant_029 | K36: =_xlfn.IFNA(VLOOKUP(C36,merchants!$A$1:$D$41,3,0),"Merchant not found") -> ecommerce | L36: =_xlfn.IFNA(VLOOKUP(C36,merchants!$A$1:$D$41,4,0),"Merchant not found") -> North | M36: =F36*(HLOOKUP(G36,$Q$1:$T$2,2,0)) -> 2.99 | N36: =IF(AND(L36<>"East",SUMIFS(merchant_workbook_pivot_table!$D$2:$D$444,merchant_workbook_pivot_table!$C$2:$C$444,E36,merchant_workbook_pivot_table!$B$2:$B$444,J36)>5000),"High-Value Merchant Day",IF(AND(L36<>"East",SUMIFS(merchant_workbook_pivot_table!$D$2:$D$444,merchant_workbook_pivot_table!$C$2:$C$444,E36,merchant_workbook_pivot_table!$B$2:$B$444,J36)>1000),"Mid-Value Merchant Day","")) -> Mid-Value Merchant Day | P36: 30 | Q36: 7384 | R36: 16 | U36: 499 | V36: 1 | X36: Merchant_032 | Y36: 12 | Z36: 14
A37: TXN100035 | B37: 327 | C37: 18 | D37: 2026-01-25 7:53:00 | E37: =LEFT(D37,10) -> 2026-01-25 | F37: 149 | G37: Card | H37: captured | I37: 98 | J37: =_xlfn.IFNA(VLOOKUP(C37,merchants!$A$1:$D$41,2,0),"Merchant not found") -> Merchant_018 | K37: =_xlfn.IFNA(VLOOKUP(C37,merchants!$A$1:$D$41,3,0),"Merchant not found") -> grocery | L37: =_xlfn.IFNA(VLOOKUP(C37,merchants!$A$1:$D$41,4,0),"Merchant not found") -> West | M37: =F37*(HLOOKUP(G37,$Q$1:$T$2,2,0)) -> 2.98 | N37: =IF(AND(L37<>"East",SUMIFS(merchant_workbook_pivot_table!$D$2:$D$444,merchant_workbook_pivot_table!$C$2:$C$444,E37,merchant_workbook_pivot_table!$B$2:$B$444,J37)>5000),"High-Value Merchant Day",IF(AND(L37<>"East",SUMIFS(merchant_workbook_pivot_table!$D$2:$D$444,merchant_workbook_pivot_table!$C$2:$C$444,E37,merchant_workbook_pivot_table!$B$2:$B$444,J37)>1000),"Mid-Value Merchant Day","")) -> Mid-Value Merchant Day | P37: 31 | Q37: 2640 | R37: 10 | S37: 49 | T37: 1 | U37: 2146 | V37: 4 | X37: Merchant_033 | Y37: 10 | Z37: 11
A38: TXN100036 | B38: 321 | C38: 16 | D38: 2026-01-25 16:31:00 | E38: =LEFT(D38,10) -> 2026-01-25 | F38: 49 | G38: UPI | H38: captured | I38: 35 | J38: =_xlfn.IFNA(VLOOKUP(C38,merchants!$A$1:$D$41,2,0),"Merchant not found") -> Merchant_016 | K38: =_xlfn.IFNA(VLOOKUP(C38,merchants!$A$1:$D$41,3,0),"Merchant not found") -> bill_payment | L38: =_xlfn.IFNA(VLOOKUP(C38,merchants!$A$1:$D$41,4,0),"Merchant not found") -> West | M38: =F38*(HLOOKUP(G38,$Q$1:$T$2,2,0)) -> 0 | N38: =IF(AND(L38<>"East",SUMIFS(merchant_workbook_pivot_table!$D$2:$D$444,merchant_workbook_pivot_table!$C$2:$C$444,E38,merchant_workbook_pivot_table!$B$2:$B$444,J38)>5000),"High-Value Merchant Day",IF(AND(L38<>"East",SUMIFS(merchant_workbook_pivot_table!$D$2:$D$444,merchant_workbook_pivot_table!$C$2:$C$444,E38,merchant_workbook_pivot_table!$B$2:$B$444,J38)>1000),"Mid-Value Merchant Day","")) | P38: 32 | Q38: 2589 | R38: 11 | S38: 1999 | T38: 1 | U38: 3498 | V38: 2 | X38: Merchant_034 | Y38: 12 | Z38: 16
A39: TXN100037 | B39: 147 | C39: 16 | D39: 2026-01-15 2:45:00 | E39: =LEFT(D39,10) -> 2026-01-15 | F39: 2999 | G39: Card | H39: captured | I39: 34 | J39: =_xlfn.IFNA(VLOOKUP(C39,merchants!$A$1:$D$41,2,0),"Merchant not found") -> Merchant_016 | K39: =_xlfn.IFNA(VLOOKUP(C39,merchants!$A$1:$D$41,3,0),"Merchant not found") -> bill_payment | L39: =_xlfn.IFNA(VLOOKUP(C39,merchants!$A$1:$D$41,4,0),"Merchant not found") -> West | M39: =F39*(HLOOKUP(G39,$Q$1:$T$2,2,0)) -> 59.98 | N39: =IF(AND(L39<>"East",SUMIFS(merchant_workbook_pivot_table!$D$2:$D$444,merchant_workbook_pivot_table!$C$2:$C$444,E39,merchant_workbook_pivot_table!$B$2:$B$444,J39)>5000),"High-Value Merchant Day",IF(AND(L39<>"East",SUMIFS(merchant_workbook_pivot_table!$D$2:$D$444,merchant_workbook_pivot_table!$C$2:$C$444,E39,merchant_workbook_pivot_table!$B$2:$B$444,J39)>1000),"Mid-Value Merchant Day","")) -> Mid-Value Merchant Day | P39: 33 | Q39: 10190 | R39: 10 | U39: 149 | V39: 1 | X39: Merchant_035 | Y39: 11 | Z39: 14
A40: TXN100038 | B40: 277 | C40: 6 | D40: 2026-01-11 10:57:00 | E40: =LEFT(D40,10) -> 2026-01-11 | F40: 1499 | G40: Card | H40: captured | I40: 17 | J40: =_xlfn.IFNA(VLOOKUP(C40,merchants!$A$1:$D$41,2,0),"Merchant not found") -> Merchant_006 | K40: =_xlfn.IFNA(VLOOKUP(C40,merchants!$A$1:$D$41,3,0),"Merchant not found") -> food_delivery | L40: =_xlfn.IFNA(VLOOKUP(C40,merchants!$A$1:$D$41,4,0),"Merchant not found") -> South | M40: =F40*(HLOOKUP(G40,$Q$1:$T$2,2,0)) -> 29.98 | N40: =IF(AND(L40<>"East",SUMIFS(merchant_workbook_pivot_table!$D$2:$D$444,merchant_workbook_pivot_table!$C$2:$C$444,E40,merchant_workbook_pivot_table!$B$2:$B$444,J40)>5000),"High-Value Merchant Day",IF(AND(L40<>"East",SUMIFS(merchant_workbook_pivot_table!$D$2:$D$444,merchant_workbook_pivot_table!$C$2:$C$444,E40,merchant_workbook_pivot_table!$B$2:$B$444,J40)>1000),"Mid-Value Merchant Day","")) -> Mid-Value Merchant Day | P40: 34 | Q40: 9635 | R40: 15 | U40: 399 | V40: 1 | X40: Merchant_036 | Y40: 12 | Z40: 16
...

Sheet merchant_workbook_pivot_table
A2: merchant_id | B2: merchant_name | C2: transaction_date | D2: SUM of amount_inr | E2: COUNTA of merchant_name
A3: 1 | B3: Merchant_001 | C3: 2026-01-05 | D3: 1499 | E3: 1
B4: Merchant_001 | C4: 2026-01-06 | D4: 149 | E4: 1
B5: Merchant_001 | C5: 2026-01-09 | D5: 5048 | E5: 2
B6: Merchant_001 | C6: 2026-01-11 | D6: 299 | E6: 1
B7: Merchant_001 | C7: 2026-01-12 | D7: 149 | E7: 1
B8: Merchant_001 | C8: 2026-01-17 | D8: 149 | E8: 1
B9: Merchant_001 | C9: 2026-01-23 | D9: 3148 | E9: 2
A10: 2 | B10: Merchant_002 | C10: 2026-01-07 | D10: 499 | E10: 1
B11: Merchant_002 | C11: 2026-01-08 | D11: 299 | E11: 1
B12: Merchant_002 | C12: 2026-01-12 | D12: 348 | E12: 2
B13: Merchant_002 | C13: 2026-01-13 | D13: 49 | E13: 1
B14: Merchant_002 | C14: 2026-01-15 | D14: 1499 | E14: 1
B15: Merchant_002 | C15: 2026-01-19 | D15: 49 | E15: 1
B16: Merchant_002 | C16: 2026-01-22 | D16: 299 | E16: 1
B17: Merchant_002 | C17: 2026-01-26 | D17: 299 | E17: 1
B18: Merchant_002 | C18: 2026-01-30 | D18: 299 | E18: 1
A19: 3 | B19: Merchant_003 | C19: 2026-01-03 | D19: 198 | E19: 2
B20: Merchant_003 | C20: 2026-01-05 | D20: 99 | E20: 1
B21: Merchant_003 | C21: 2026-01-06 | D21: 898 | E21: 2
B22: Merchant_003 | C22: 2026-01-07 | D22: 798 | E22: 2
B23: Merchant_003 | C23: 2026-01-08 | D23: 149 | E23: 1
B24: Merchant_003 | C24: 2026-01-13 | D24: 198 | E24: 2
B25: Merchant_003 | C25: 2026-01-16 | D25: 4999 | E25: 1
B26: Merchant_003 | C26: 2026-01-20 | D26: 99 | E26: 1
B27: Merchant_003 | C27: 2026-01-22 | D27: 499 | E27: 1
B28: Merchant_003 | C28: 2026-01-23 | D28: 49 | E28: 1
B29: Merchant_003 | C29: 2026-01-26 | D29: 149 | E29: 1
B30: Merchant_003 | C30: 2026-01-29 | D30: 49 | E30: 1
B31: Merchant_003 | C31: 2026-01-30 | D31: 49 | E31: 1
A32: 4 | B32: Merchant_004 | C32: 2026-01-02 | D32: 149 | E32: 1
B33: Merchant_004 | C33: 2026-01-12 | D33: 49 | E33: 1
B34: Merchant_004 | C34: 2026-01-13 | D34: 948 | E34: 2
B35: Merchant_004 | C35: 2026-01-16 | D35: 799 | E35: 1
B36: Merchant_004 | C36: 2026-01-17 | D36: 1499 | E36: 1
B37: Merchant_004 | C37: 2026-01-24 | D37: 1499 | E37: 1
B38: Merchant_004 | C38: 2026-01-25 | D38: 1998 | E38: 2
A39: 5 | B39: Merchant_005 | C39: 2026-01-01 | D39: 499 | E39: 1
B40: Merchant_005 | C40: 2026-01-03 | D40: 499 | E40: 1
B41: Merchant_005 | C41: 2026-01-09 | D41: 348 | E41: 2
...
